[2024-05-31T08:02:30.930+0000] {local_task_job_runner.py:120} INFO - ::group::Pre task execution logs
[2024-05-31T08:02:30.947+0000] {taskinstance.py:2073} INFO - Dependencies all met for dep_context=non-requeueable deps ti=<TaskInstance: stored_procedures.export_json manual__2024-05-31T07:57:06.814544+00:00 [queued]>
[2024-05-31T08:02:30.955+0000] {taskinstance.py:2073} INFO - Dependencies all met for dep_context=requeueable deps ti=<TaskInstance: stored_procedures.export_json manual__2024-05-31T07:57:06.814544+00:00 [queued]>
[2024-05-31T08:02:30.956+0000] {taskinstance.py:2303} INFO - Starting attempt 2 of 2
[2024-05-31T08:02:30.967+0000] {taskinstance.py:2327} INFO - Executing <Task(PythonOperator): export_json> on 2024-05-31 07:57:06.814544+00:00
[2024-05-31T08:02:30.972+0000] {warnings.py:110} WARNING - /home/***/.local/lib/python3.12/site-packages/***/task/task_runner/standard_task_runner.py:61: DeprecationWarning: This process (pid=190) is multi-threaded, use of fork() may lead to deadlocks in the child.
  pid = os.fork()

[2024-05-31T08:02:30.974+0000] {standard_task_runner.py:63} INFO - Started process 192 to run task
[2024-05-31T08:02:30.973+0000] {standard_task_runner.py:90} INFO - Running: ['***', 'tasks', 'run', 'stored_procedures', 'export_json', 'manual__2024-05-31T07:57:06.814544+00:00', '--job-id', '504', '--raw', '--subdir', 'DAGS_FOLDER/dag_example.py', '--cfg-path', '/tmp/tmptlppjeop']
[2024-05-31T08:02:30.976+0000] {standard_task_runner.py:91} INFO - Job 504: Subtask export_json
[2024-05-31T08:02:31.017+0000] {task_command.py:426} INFO - Running <TaskInstance: stored_procedures.export_json manual__2024-05-31T07:57:06.814544+00:00 [running]> on host 29c09f03cc50
[2024-05-31T08:02:31.092+0000] {taskinstance.py:2644} INFO - Exporting env vars: AIRFLOW_CTX_DAG_OWNER='Yamin' AIRFLOW_CTX_DAG_ID='stored_procedures' AIRFLOW_CTX_TASK_ID='export_json' AIRFLOW_CTX_EXECUTION_DATE='2024-05-31T07:57:06.814544+00:00' AIRFLOW_CTX_TRY_NUMBER='2' AIRFLOW_CTX_DAG_RUN_ID='manual__2024-05-31T07:57:06.814544+00:00'
[2024-05-31T08:02:31.094+0000] {taskinstance.py:430} INFO - ::endgroup::
[2024-05-31T08:02:31.886+0000] {taskinstance.py:441} INFO - ::group::Post task execution logs
[2024-05-31T08:02:31.887+0000] {taskinstance.py:2890} ERROR - Task failed with exception
Traceback (most recent call last):
  File "/home/airflow/.local/lib/python3.12/site-packages/airflow/models/taskinstance.py", line 465, in _execute_task
    result = _execute_callable(context=context, **execute_callable_kwargs)
             ^^^^^^^^^^^^^^^^^^^^^^^^^^^^^^^^^^^^^^^^^^^^^^^^^^^^^^^^^^^^^
  File "/home/airflow/.local/lib/python3.12/site-packages/airflow/models/taskinstance.py", line 432, in _execute_callable
    return execute_callable(context=context, **execute_callable_kwargs)
           ^^^^^^^^^^^^^^^^^^^^^^^^^^^^^^^^^^^^^^^^^^^^^^^^^^^^^^^^^^^^
  File "/home/airflow/.local/lib/python3.12/site-packages/airflow/models/baseoperator.py", line 400, in wrapper
    return func(self, *args, **kwargs)
           ^^^^^^^^^^^^^^^^^^^^^^^^^^^
  File "/home/airflow/.local/lib/python3.12/site-packages/airflow/operators/python.py", line 235, in execute
    return_value = self.execute_callable()
                   ^^^^^^^^^^^^^^^^^^^^^^^
  File "/home/airflow/.local/lib/python3.12/site-packages/airflow/operators/python.py", line 252, in execute_callable
    return self.python_callable(*self.op_args, **self.op_kwargs)
           ^^^^^^^^^^^^^^^^^^^^^^^^^^^^^^^^^^^^^^^^^^^^^^^^^^^^^
  File "/opt/airflow/dags/dag_example.py", line 214, in create_json
    json.dump(data_list, json_file, indent=2)
  File "/usr/local/lib/python3.12/json/__init__.py", line 179, in dump
    for chunk in iterable:
  File "/usr/local/lib/python3.12/json/encoder.py", line 430, in _iterencode
    yield from _iterencode_list(o, _current_indent_level)
  File "/usr/local/lib/python3.12/json/encoder.py", line 326, in _iterencode_list
    yield from chunks
  File "/usr/local/lib/python3.12/json/encoder.py", line 406, in _iterencode_dict
    yield from chunks
  File "/usr/local/lib/python3.12/json/encoder.py", line 439, in _iterencode
    o = _default(o)
        ^^^^^^^^^^^
  File "/usr/local/lib/python3.12/json/encoder.py", line 180, in default
    raise TypeError(f'Object of type {o.__class__.__name__} '
TypeError: Object of type Decimal is not JSON serializable
[2024-05-31T08:02:31.902+0000] {taskinstance.py:1205} INFO - Marking task as FAILED. dag_id=stored_procedures, task_id=export_json, execution_date=20240531T075706, start_date=20240531T080230, end_date=20240531T080231
[2024-05-31T08:02:31.919+0000] {standard_task_runner.py:110} ERROR - Failed to execute job 504 for task export_json (Object of type Decimal is not JSON serializable; 192)
[2024-05-31T08:02:31.953+0000] {local_task_job_runner.py:240} INFO - Task exited with return code 1
[2024-05-31T08:02:31.981+0000] {taskinstance.py:3482} INFO - 0 downstream tasks scheduled from follow-on schedule check
[2024-05-31T08:02:31.989+0000] {local_task_job_runner.py:222} INFO - ::endgroup::
