[2024-05-28T14:34:17.707+0000] {local_task_job_runner.py:120} INFO - ::group::Pre task execution logs
[2024-05-28T14:34:17.732+0000] {taskinstance.py:2073} INFO - Dependencies all met for dep_context=non-requeueable deps ti=<TaskInstance: stored_procedures.move_file_task manual__2024-05-28T14:29:13.884993+00:00 [queued]>
[2024-05-28T14:34:17.739+0000] {taskinstance.py:2073} INFO - Dependencies all met for dep_context=requeueable deps ti=<TaskInstance: stored_procedures.move_file_task manual__2024-05-28T14:29:13.884993+00:00 [queued]>
[2024-05-28T14:34:17.740+0000] {taskinstance.py:2303} INFO - Starting attempt 2 of 2
[2024-05-28T14:34:17.753+0000] {taskinstance.py:2327} INFO - Executing <Task(PythonOperator): move_file_task> on 2024-05-28 14:29:13.884993+00:00
[2024-05-28T14:34:17.761+0000] {warnings.py:110} WARNING - /home/***/.local/lib/python3.12/site-packages/***/task/task_runner/standard_task_runner.py:61: DeprecationWarning: This process (pid=449) is multi-threaded, use of fork() may lead to deadlocks in the child.
  pid = os.fork()

[2024-05-28T14:34:17.763+0000] {standard_task_runner.py:63} INFO - Started process 454 to run task
[2024-05-28T14:34:17.764+0000] {standard_task_runner.py:90} INFO - Running: ['***', 'tasks', 'run', 'stored_procedures', 'move_file_task', 'manual__2024-05-28T14:29:13.884993+00:00', '--job-id', '64', '--raw', '--subdir', 'DAGS_FOLDER/dag_example.py', '--cfg-path', '/tmp/tmpwjye1ll2']
[2024-05-28T14:34:17.767+0000] {standard_task_runner.py:91} INFO - Job 64: Subtask move_file_task
[2024-05-28T14:34:17.827+0000] {task_command.py:426} INFO - Running <TaskInstance: stored_procedures.move_file_task manual__2024-05-28T14:29:13.884993+00:00 [running]> on host 29c09f03cc50
[2024-05-28T14:34:17.916+0000] {taskinstance.py:2644} INFO - Exporting env vars: AIRFLOW_CTX_DAG_OWNER='Yamin' AIRFLOW_CTX_DAG_ID='stored_procedures' AIRFLOW_CTX_TASK_ID='move_file_task' AIRFLOW_CTX_EXECUTION_DATE='2024-05-28T14:29:13.884993+00:00' AIRFLOW_CTX_TRY_NUMBER='2' AIRFLOW_CTX_DAG_RUN_ID='manual__2024-05-28T14:29:13.884993+00:00'
[2024-05-28T14:34:17.917+0000] {taskinstance.py:430} INFO - ::endgroup::
[2024-05-28T14:34:17.944+0000] {taskinstance.py:441} INFO - ::group::Post task execution logs
[2024-05-28T14:34:17.944+0000] {taskinstance.py:2890} ERROR - Task failed with exception
Traceback (most recent call last):
  File "/usr/local/lib/python3.12/shutil.py", line 886, in move
    os.rename(src, real_dst)
FileNotFoundError: [Errno 2] No such file or directory: './dags/csv/driver_standings_total.csv' -> './dags/csv/failed'

During handling of the above exception, another exception occurred:

Traceback (most recent call last):
  File "/home/airflow/.local/lib/python3.12/site-packages/airflow/models/taskinstance.py", line 465, in _execute_task
    result = _execute_callable(context=context, **execute_callable_kwargs)
             ^^^^^^^^^^^^^^^^^^^^^^^^^^^^^^^^^^^^^^^^^^^^^^^^^^^^^^^^^^^^^
  File "/home/airflow/.local/lib/python3.12/site-packages/airflow/models/taskinstance.py", line 432, in _execute_callable
    return execute_callable(context=context, **execute_callable_kwargs)
           ^^^^^^^^^^^^^^^^^^^^^^^^^^^^^^^^^^^^^^^^^^^^^^^^^^^^^^^^^^^^
  File "/home/airflow/.local/lib/python3.12/site-packages/airflow/models/baseoperator.py", line 400, in wrapper
    return func(self, *args, **kwargs)
           ^^^^^^^^^^^^^^^^^^^^^^^^^^^
  File "/home/airflow/.local/lib/python3.12/site-packages/airflow/operators/python.py", line 235, in execute
    return_value = self.execute_callable()
                   ^^^^^^^^^^^^^^^^^^^^^^^
  File "/home/airflow/.local/lib/python3.12/site-packages/airflow/operators/python.py", line 252, in execute_callable
    return self.python_callable(*self.op_args, **self.op_kwargs)
           ^^^^^^^^^^^^^^^^^^^^^^^^^^^^^^^^^^^^^^^^^^^^^^^^^^^^^
  File "/opt/airflow/dags/dag_example.py", line 113, in move_file
    shutil.move(file_path, destination_directory)
  File "/usr/local/lib/python3.12/shutil.py", line 906, in move
    copy_function(src, real_dst)
  File "/usr/local/lib/python3.12/shutil.py", line 475, in copy2
    copyfile(src, dst, follow_symlinks=follow_symlinks)
  File "/usr/local/lib/python3.12/shutil.py", line 260, in copyfile
    with open(src, 'rb') as fsrc:
         ^^^^^^^^^^^^^^^
FileNotFoundError: [Errno 2] No such file or directory: './dags/csv/driver_standings_total.csv'
[2024-05-28T14:34:17.959+0000] {taskinstance.py:1205} INFO - Marking task as FAILED. dag_id=stored_procedures, task_id=move_file_task, execution_date=20240528T142913, start_date=20240528T143417, end_date=20240528T143417
[2024-05-28T14:34:17.974+0000] {standard_task_runner.py:110} ERROR - Failed to execute job 64 for task move_file_task ([Errno 2] No such file or directory: './dags/csv/driver_standings_total.csv'; 454)
[2024-05-28T14:34:18.017+0000] {local_task_job_runner.py:240} INFO - Task exited with return code 1
[2024-05-28T14:34:18.048+0000] {taskinstance.py:3482} INFO - 0 downstream tasks scheduled from follow-on schedule check
[2024-05-28T14:34:18.050+0000] {local_task_job_runner.py:222} INFO - ::endgroup::
