[2024-05-28T14:34:34.933+0000] {local_task_job_runner.py:120} INFO - ::group::Pre task execution logs
[2024-05-28T14:34:34.956+0000] {taskinstance.py:2073} INFO - Dependencies all met for dep_context=non-requeueable deps ti=<TaskInstance: stored_procedures.file_sensor_task manual__2024-05-28T14:29:31.227704+00:00 [queued]>
[2024-05-28T14:34:34.966+0000] {taskinstance.py:2073} INFO - Dependencies all met for dep_context=requeueable deps ti=<TaskInstance: stored_procedures.file_sensor_task manual__2024-05-28T14:29:31.227704+00:00 [queued]>
[2024-05-28T14:34:34.967+0000] {taskinstance.py:2303} INFO - Starting attempt 2 of 2
[2024-05-28T14:34:34.982+0000] {taskinstance.py:2327} INFO - Executing <Task(FileSensor): file_sensor_task> on 2024-05-28 14:29:31.227704+00:00
[2024-05-28T14:34:34.989+0000] {warnings.py:110} WARNING - /home/***/.local/lib/python3.12/site-packages/***/task/task_runner/standard_task_runner.py:61: DeprecationWarning: This process (pid=469) is multi-threaded, use of fork() may lead to deadlocks in the child.
  pid = os.fork()

[2024-05-28T14:34:34.991+0000] {standard_task_runner.py:63} INFO - Started process 473 to run task
[2024-05-28T14:34:34.992+0000] {standard_task_runner.py:90} INFO - Running: ['***', 'tasks', 'run', 'stored_procedures', 'file_sensor_task', 'manual__2024-05-28T14:29:31.227704+00:00', '--job-id', '68', '--raw', '--subdir', 'DAGS_FOLDER/dag_example.py', '--cfg-path', '/tmp/tmpx82p3v4b']
[2024-05-28T14:34:34.995+0000] {standard_task_runner.py:91} INFO - Job 68: Subtask file_sensor_task
[2024-05-28T14:34:35.052+0000] {task_command.py:426} INFO - Running <TaskInstance: stored_procedures.file_sensor_task manual__2024-05-28T14:29:31.227704+00:00 [running]> on host 29c09f03cc50
[2024-05-28T14:34:35.142+0000] {taskinstance.py:2644} INFO - Exporting env vars: AIRFLOW_CTX_DAG_OWNER='Yamin' AIRFLOW_CTX_DAG_ID='stored_procedures' AIRFLOW_CTX_TASK_ID='file_sensor_task' AIRFLOW_CTX_EXECUTION_DATE='2024-05-28T14:29:31.227704+00:00' AIRFLOW_CTX_TRY_NUMBER='2' AIRFLOW_CTX_DAG_RUN_ID='manual__2024-05-28T14:29:31.227704+00:00'
[2024-05-28T14:34:35.144+0000] {taskinstance.py:430} INFO - ::endgroup::
[2024-05-28T14:34:35.158+0000] {baseoperator.py:399} WARNING - FileSensor.execute cannot be called outside TaskInstance!
[2024-05-28T14:34:35.171+0000] {taskinstance.py:441} INFO - ::group::Post task execution logs
[2024-05-28T14:34:35.183+0000] {taskinstance.py:2890} ERROR - Task failed with exception
Traceback (most recent call last):
  File "/home/airflow/.local/lib/python3.12/site-packages/airflow/models/taskinstance.py", line 465, in _execute_task
    result = _execute_callable(context=context, **execute_callable_kwargs)
             ^^^^^^^^^^^^^^^^^^^^^^^^^^^^^^^^^^^^^^^^^^^^^^^^^^^^^^^^^^^^^
  File "/home/airflow/.local/lib/python3.12/site-packages/airflow/models/taskinstance.py", line 432, in _execute_callable
    return execute_callable(context=context, **execute_callable_kwargs)
           ^^^^^^^^^^^^^^^^^^^^^^^^^^^^^^^^^^^^^^^^^^^^^^^^^^^^^^^^^^^^
  File "/home/airflow/.local/lib/python3.12/site-packages/airflow/models/baseoperator.py", line 400, in wrapper
    return func(self, *args, **kwargs)
           ^^^^^^^^^^^^^^^^^^^^^^^^^^^
  File "/home/airflow/.local/lib/python3.12/site-packages/airflow/sensors/filesystem.py", line 99, in execute
    super().execute(context=context)
  File "/home/airflow/.local/lib/python3.12/site-packages/airflow/models/baseoperator.py", line 400, in wrapper
    return func(self, *args, **kwargs)
           ^^^^^^^^^^^^^^^^^^^^^^^^^^^
  File "/home/airflow/.local/lib/python3.12/site-packages/airflow/sensors/base.py", line 264, in execute
    raise e
  File "/home/airflow/.local/lib/python3.12/site-packages/airflow/sensors/base.py", line 246, in execute
    poke_return = self.poke(context)
                  ^^^^^^^^^^^^^^^^^^
  File "/home/airflow/.local/lib/python3.12/site-packages/airflow/sensors/filesystem.py", line 85, in poke
    self.log.info("Poking for file %s", self.path)
                                        ^^^^^^^^^
  File "/usr/local/lib/python3.12/functools.py", line 995, in __get__
    val = self.func(instance)
          ^^^^^^^^^^^^^^^^^^^
  File "/home/airflow/.local/lib/python3.12/site-packages/airflow/sensors/filesystem.py", line 79, in path
    hook = FSHook(self.fs_conn_id)
           ^^^^^^^^^^^^^^^^^^^^^^^
  File "/home/airflow/.local/lib/python3.12/site-packages/airflow/hooks/filesystem.py", line 64, in __init__
    conn = self.get_connection(fs_conn_id)
           ^^^^^^^^^^^^^^^^^^^^^^^^^^^^^^^
  File "/home/airflow/.local/lib/python3.12/site-packages/airflow/hooks/base.py", line 83, in get_connection
    conn = Connection.get_connection_from_secrets(conn_id)
           ^^^^^^^^^^^^^^^^^^^^^^^^^^^^^^^^^^^^^^^^^^^^^^^
  File "/home/airflow/.local/lib/python3.12/site-packages/airflow/models/connection.py", line 519, in get_connection_from_secrets
    raise AirflowNotFoundException(f"The conn_id `{conn_id}` isn't defined")
airflow.exceptions.AirflowNotFoundException: The conn_id `fs_default` isn't defined
[2024-05-28T14:34:35.189+0000] {taskinstance.py:1205} INFO - Marking task as FAILED. dag_id=stored_procedures, task_id=file_sensor_task, execution_date=20240528T142931, start_date=20240528T143434, end_date=20240528T143435
[2024-05-28T14:34:35.205+0000] {standard_task_runner.py:110} ERROR - Failed to execute job 68 for task file_sensor_task (The conn_id `fs_default` isn't defined; 473)
[2024-05-28T14:34:35.246+0000] {local_task_job_runner.py:240} INFO - Task exited with return code 1
[2024-05-28T14:34:35.267+0000] {taskinstance.py:3482} INFO - 0 downstream tasks scheduled from follow-on schedule check
[2024-05-28T14:34:35.269+0000] {local_task_job_runner.py:222} INFO - ::endgroup::
