[2024-05-28T15:19:01.744+0000] {local_task_job_runner.py:120} INFO - ::group::Pre task execution logs
[2024-05-28T15:19:01.766+0000] {taskinstance.py:2073} INFO - Dependencies all met for dep_context=non-requeueable deps ti=<TaskInstance: stored_procedures.r2p_drivers manual__2024-05-28T15:13:56.349229+00:00 [queued]>
[2024-05-28T15:19:01.773+0000] {taskinstance.py:2073} INFO - Dependencies all met for dep_context=requeueable deps ti=<TaskInstance: stored_procedures.r2p_drivers manual__2024-05-28T15:13:56.349229+00:00 [queued]>
[2024-05-28T15:19:01.774+0000] {taskinstance.py:2303} INFO - Starting attempt 2 of 2
[2024-05-28T15:19:01.786+0000] {taskinstance.py:2327} INFO - Executing <Task(PythonOperator): r2p_drivers> on 2024-05-28 15:13:56.349229+00:00
[2024-05-28T15:19:01.794+0000] {warnings.py:110} WARNING - /home/***/.local/lib/python3.12/site-packages/***/task/task_runner/standard_task_runner.py:61: DeprecationWarning: This process (pid=1230) is multi-threaded, use of fork() may lead to deadlocks in the child.
  pid = os.fork()

[2024-05-28T15:19:01.796+0000] {standard_task_runner.py:63} INFO - Started process 1232 to run task
[2024-05-28T15:19:01.797+0000] {standard_task_runner.py:90} INFO - Running: ['***', 'tasks', 'run', 'stored_procedures', 'r2p_drivers', 'manual__2024-05-28T15:13:56.349229+00:00', '--job-id', '123', '--raw', '--subdir', 'DAGS_FOLDER/dag_example.py', '--cfg-path', '/tmp/tmpa3n3gfdp']
[2024-05-28T15:19:01.799+0000] {standard_task_runner.py:91} INFO - Job 123: Subtask r2p_drivers
[2024-05-28T15:19:01.848+0000] {task_command.py:426} INFO - Running <TaskInstance: stored_procedures.r2p_drivers manual__2024-05-28T15:13:56.349229+00:00 [running]> on host 29c09f03cc50
[2024-05-28T15:19:01.931+0000] {taskinstance.py:2644} INFO - Exporting env vars: AIRFLOW_CTX_DAG_OWNER='Yamin' AIRFLOW_CTX_DAG_ID='stored_procedures' AIRFLOW_CTX_TASK_ID='r2p_drivers' AIRFLOW_CTX_EXECUTION_DATE='2024-05-28T15:13:56.349229+00:00' AIRFLOW_CTX_TRY_NUMBER='2' AIRFLOW_CTX_DAG_RUN_ID='manual__2024-05-28T15:13:56.349229+00:00'
[2024-05-28T15:19:01.933+0000] {taskinstance.py:430} INFO - ::endgroup::
[2024-05-28T15:19:01.952+0000] {taskinstance.py:441} INFO - ::group::Post task execution logs
[2024-05-28T15:19:01.953+0000] {taskinstance.py:2890} ERROR - Task failed with exception
Traceback (most recent call last):
  File "/home/airflow/.local/lib/python3.12/site-packages/airflow/models/taskinstance.py", line 465, in _execute_task
    result = _execute_callable(context=context, **execute_callable_kwargs)
             ^^^^^^^^^^^^^^^^^^^^^^^^^^^^^^^^^^^^^^^^^^^^^^^^^^^^^^^^^^^^^
  File "/home/airflow/.local/lib/python3.12/site-packages/airflow/models/taskinstance.py", line 432, in _execute_callable
    return execute_callable(context=context, **execute_callable_kwargs)
           ^^^^^^^^^^^^^^^^^^^^^^^^^^^^^^^^^^^^^^^^^^^^^^^^^^^^^^^^^^^^
  File "/home/airflow/.local/lib/python3.12/site-packages/airflow/models/baseoperator.py", line 400, in wrapper
    return func(self, *args, **kwargs)
           ^^^^^^^^^^^^^^^^^^^^^^^^^^^
  File "/home/airflow/.local/lib/python3.12/site-packages/airflow/operators/python.py", line 235, in execute
    return_value = self.execute_callable()
                   ^^^^^^^^^^^^^^^^^^^^^^^
  File "/home/airflow/.local/lib/python3.12/site-packages/airflow/operators/python.py", line 252, in execute_callable
    return self.python_callable(*self.op_args, **self.op_kwargs)
           ^^^^^^^^^^^^^^^^^^^^^^^^^^^^^^^^^^^^^^^^^^^^^^^^^^^^^
  File "/opt/airflow/dags/dag_example.py", line 106, in insert_into_processed_drivers
    cur.execute("CALL insert_into_processed_drivers();")
psycopg2.errors.UniqueViolation: duplicate key value violates unique constraint "drivers_pkey"
DETAIL:  Key (unique_driver_id)=(1) already exists.
CONTEXT:  SQL statement "INSERT INTO processed.drivers (
        unique_driver_id,
        driver_id,
        driver_ref,
        number,
        code,
        forename,
        surname,
        dob,
        nationality,
        url,
        created_date,
        last_updated_date
    )
    SELECT
        unique_driver_id,
        driver_id,
        driver_ref,
        number,
        code,
        forename,
        surname,
        dob,
        nationality,
        url,
        created_date,
        last_updated_date
    FROM raw.drivers"
PL/pgSQL function insert_into_processed_drivers() line 7 at SQL statement

[2024-05-28T15:19:01.966+0000] {taskinstance.py:1205} INFO - Marking task as FAILED. dag_id=stored_procedures, task_id=r2p_drivers, execution_date=20240528T151356, start_date=20240528T151901, end_date=20240528T151901
[2024-05-28T15:19:01.976+0000] {standard_task_runner.py:110} ERROR - Failed to execute job 123 for task r2p_drivers (duplicate key value violates unique constraint "drivers_pkey"
DETAIL:  Key (unique_driver_id)=(1) already exists.
CONTEXT:  SQL statement "INSERT INTO processed.drivers (
        unique_driver_id,
        driver_id,
        driver_ref,
        number,
        code,
        forename,
        surname,
        dob,
        nationality,
        url,
        created_date,
        last_updated_date
    )
    SELECT
        unique_driver_id,
        driver_id,
        driver_ref,
        number,
        code,
        forename,
        surname,
        dob,
        nationality,
        url,
        created_date,
        last_updated_date
    FROM raw.drivers"
PL/pgSQL function insert_into_processed_drivers() line 7 at SQL statement
; 1232)
[2024-05-28T15:19:02.011+0000] {local_task_job_runner.py:240} INFO - Task exited with return code 1
[2024-05-28T15:19:02.029+0000] {taskinstance.py:3482} INFO - 0 downstream tasks scheduled from follow-on schedule check
[2024-05-28T15:19:02.032+0000] {local_task_job_runner.py:222} INFO - ::endgroup::
