[2024-05-30T15:18:11.962+0000] {local_task_job_runner.py:120} INFO - ::group::Pre task execution logs
[2024-05-30T15:18:11.981+0000] {taskinstance.py:2073} INFO - Dependencies all met for dep_context=non-requeueable deps ti=<TaskInstance: stored_procedures.export_json manual__2024-05-30T15:17:47.262180+00:00 [queued]>
[2024-05-30T15:18:11.990+0000] {taskinstance.py:2073} INFO - Dependencies all met for dep_context=requeueable deps ti=<TaskInstance: stored_procedures.export_json manual__2024-05-30T15:17:47.262180+00:00 [queued]>
[2024-05-30T15:18:11.991+0000] {taskinstance.py:2303} INFO - Starting attempt 1 of 2
[2024-05-30T15:18:12.005+0000] {taskinstance.py:2327} INFO - Executing <Task(PythonOperator): export_json> on 2024-05-30 15:17:47.262180+00:00
[2024-05-30T15:18:12.012+0000] {warnings.py:110} WARNING - /home/***/.local/lib/python3.12/site-packages/***/task/task_runner/standard_task_runner.py:61: DeprecationWarning: This process (pid=645) is multi-threaded, use of fork() may lead to deadlocks in the child.
  pid = os.fork()

[2024-05-30T15:18:12.013+0000] {standard_task_runner.py:63} INFO - Started process 647 to run task
[2024-05-30T15:18:12.013+0000] {standard_task_runner.py:90} INFO - Running: ['***', 'tasks', 'run', 'stored_procedures', 'export_json', 'manual__2024-05-30T15:17:47.262180+00:00', '--job-id', '443', '--raw', '--subdir', 'DAGS_FOLDER/dag_example.py', '--cfg-path', '/tmp/tmpwf36ykjl']
[2024-05-30T15:18:12.016+0000] {standard_task_runner.py:91} INFO - Job 443: Subtask export_json
[2024-05-30T15:18:12.065+0000] {task_command.py:426} INFO - Running <TaskInstance: stored_procedures.export_json manual__2024-05-30T15:17:47.262180+00:00 [running]> on host 29c09f03cc50
[2024-05-30T15:18:12.145+0000] {taskinstance.py:2644} INFO - Exporting env vars: AIRFLOW_CTX_DAG_OWNER='Yamin' AIRFLOW_CTX_DAG_ID='stored_procedures' AIRFLOW_CTX_TASK_ID='export_json' AIRFLOW_CTX_EXECUTION_DATE='2024-05-30T15:17:47.262180+00:00' AIRFLOW_CTX_TRY_NUMBER='1' AIRFLOW_CTX_DAG_RUN_ID='manual__2024-05-30T15:17:47.262180+00:00'
[2024-05-30T15:18:12.147+0000] {taskinstance.py:430} INFO - ::endgroup::
[2024-05-30T15:18:12.171+0000] {taskinstance.py:441} INFO - ::group::Post task execution logs
[2024-05-30T15:18:12.173+0000] {taskinstance.py:2890} ERROR - Task failed with exception
Traceback (most recent call last):
  File "/home/airflow/.local/lib/python3.12/site-packages/airflow/models/taskinstance.py", line 465, in _execute_task
    result = _execute_callable(context=context, **execute_callable_kwargs)
             ^^^^^^^^^^^^^^^^^^^^^^^^^^^^^^^^^^^^^^^^^^^^^^^^^^^^^^^^^^^^^
  File "/home/airflow/.local/lib/python3.12/site-packages/airflow/models/taskinstance.py", line 432, in _execute_callable
    return execute_callable(context=context, **execute_callable_kwargs)
           ^^^^^^^^^^^^^^^^^^^^^^^^^^^^^^^^^^^^^^^^^^^^^^^^^^^^^^^^^^^^
  File "/home/airflow/.local/lib/python3.12/site-packages/airflow/models/baseoperator.py", line 400, in wrapper
    return func(self, *args, **kwargs)
           ^^^^^^^^^^^^^^^^^^^^^^^^^^^
  File "/home/airflow/.local/lib/python3.12/site-packages/airflow/operators/python.py", line 235, in execute
    return_value = self.execute_callable()
                   ^^^^^^^^^^^^^^^^^^^^^^^
  File "/home/airflow/.local/lib/python3.12/site-packages/airflow/operators/python.py", line 252, in execute_callable
    return self.python_callable(*self.op_args, **self.op_kwargs)
           ^^^^^^^^^^^^^^^^^^^^^^^^^^^^^^^^^^^^^^^^^^^^^^^^^^^^^
  File "/opt/airflow/dags/dag_example.py", line 149, in create_json
    json.dump(data_list, json_file, indent=2)
  File "/usr/local/lib/python3.12/json/__init__.py", line 179, in dump
    for chunk in iterable:
  File "/usr/local/lib/python3.12/json/encoder.py", line 430, in _iterencode
    yield from _iterencode_list(o, _current_indent_level)
  File "/usr/local/lib/python3.12/json/encoder.py", line 326, in _iterencode_list
    yield from chunks
  File "/usr/local/lib/python3.12/json/encoder.py", line 406, in _iterencode_dict
    yield from chunks
  File "/usr/local/lib/python3.12/json/encoder.py", line 439, in _iterencode
    o = _default(o)
        ^^^^^^^^^^^
  File "/usr/local/lib/python3.12/json/encoder.py", line 180, in default
    raise TypeError(f'Object of type {o.__class__.__name__} '
TypeError: Object of type datetime is not JSON serializable
[2024-05-30T15:18:12.186+0000] {taskinstance.py:1205} INFO - Marking task as UP_FOR_RETRY. dag_id=stored_procedures, task_id=export_json, execution_date=20240530T151747, start_date=20240530T151811, end_date=20240530T151812
[2024-05-30T15:18:12.197+0000] {standard_task_runner.py:110} ERROR - Failed to execute job 443 for task export_json (Object of type datetime is not JSON serializable; 647)
[2024-05-30T15:18:12.228+0000] {local_task_job_runner.py:240} INFO - Task exited with return code 1
[2024-05-30T15:18:12.253+0000] {taskinstance.py:3482} INFO - 0 downstream tasks scheduled from follow-on schedule check
[2024-05-30T15:18:12.256+0000] {local_task_job_runner.py:222} INFO - ::endgroup::
