[2024-05-30T11:36:23.938+0000] {local_task_job_runner.py:120} INFO - ::group::Pre task execution logs
[2024-05-30T11:36:23.961+0000] {taskinstance.py:2073} INFO - Dependencies all met for dep_context=non-requeueable deps ti=<TaskInstance: stored_procedures.load_reference_table manual__2024-05-30T11:26:08.851759+00:00 [queued]>
[2024-05-30T11:36:23.968+0000] {taskinstance.py:2073} INFO - Dependencies all met for dep_context=requeueable deps ti=<TaskInstance: stored_procedures.load_reference_table manual__2024-05-30T11:26:08.851759+00:00 [queued]>
[2024-05-30T11:36:23.970+0000] {taskinstance.py:2303} INFO - Starting attempt 2 of 2
[2024-05-30T11:36:23.983+0000] {taskinstance.py:2327} INFO - Executing <Task(PythonOperator): load_reference_table> on 2024-05-30 11:26:08.851759+00:00
[2024-05-30T11:36:23.989+0000] {warnings.py:110} WARNING - /home/***/.local/lib/python3.12/site-packages/***/task/task_runner/standard_task_runner.py:61: DeprecationWarning: This process (pid=288) is multi-threaded, use of fork() may lead to deadlocks in the child.
  pid = os.fork()

[2024-05-30T11:36:23.991+0000] {standard_task_runner.py:63} INFO - Started process 290 to run task
[2024-05-30T11:36:23.991+0000] {standard_task_runner.py:90} INFO - Running: ['***', 'tasks', 'run', 'stored_procedures', 'load_reference_table', 'manual__2024-05-30T11:26:08.851759+00:00', '--job-id', '249', '--raw', '--subdir', 'DAGS_FOLDER/dag_example.py', '--cfg-path', '/tmp/tmp23oma6a7']
[2024-05-30T11:36:23.993+0000] {standard_task_runner.py:91} INFO - Job 249: Subtask load_reference_table
[2024-05-30T11:36:24.045+0000] {task_command.py:426} INFO - Running <TaskInstance: stored_procedures.load_reference_table manual__2024-05-30T11:26:08.851759+00:00 [running]> on host 29c09f03cc50
[2024-05-30T11:36:24.122+0000] {taskinstance.py:2644} INFO - Exporting env vars: AIRFLOW_CTX_DAG_OWNER='Yamin' AIRFLOW_CTX_DAG_ID='stored_procedures' AIRFLOW_CTX_TASK_ID='load_reference_table' AIRFLOW_CTX_EXECUTION_DATE='2024-05-30T11:26:08.851759+00:00' AIRFLOW_CTX_TRY_NUMBER='2' AIRFLOW_CTX_DAG_RUN_ID='manual__2024-05-30T11:26:08.851759+00:00'
[2024-05-30T11:36:24.124+0000] {taskinstance.py:430} INFO - ::endgroup::
[2024-05-30T11:36:24.143+0000] {taskinstance.py:441} INFO - ::group::Post task execution logs
[2024-05-30T11:36:24.144+0000] {taskinstance.py:2890} ERROR - Task failed with exception
Traceback (most recent call last):
  File "/home/airflow/.local/lib/python3.12/site-packages/airflow/models/taskinstance.py", line 465, in _execute_task
    result = _execute_callable(context=context, **execute_callable_kwargs)
             ^^^^^^^^^^^^^^^^^^^^^^^^^^^^^^^^^^^^^^^^^^^^^^^^^^^^^^^^^^^^^
  File "/home/airflow/.local/lib/python3.12/site-packages/airflow/models/taskinstance.py", line 432, in _execute_callable
    return execute_callable(context=context, **execute_callable_kwargs)
           ^^^^^^^^^^^^^^^^^^^^^^^^^^^^^^^^^^^^^^^^^^^^^^^^^^^^^^^^^^^^
  File "/home/airflow/.local/lib/python3.12/site-packages/airflow/models/baseoperator.py", line 400, in wrapper
    return func(self, *args, **kwargs)
           ^^^^^^^^^^^^^^^^^^^^^^^^^^^
  File "/home/airflow/.local/lib/python3.12/site-packages/airflow/operators/python.py", line 235, in execute
    return_value = self.execute_callable()
                   ^^^^^^^^^^^^^^^^^^^^^^^
  File "/home/airflow/.local/lib/python3.12/site-packages/airflow/operators/python.py", line 252, in execute_callable
    return self.python_callable(*self.op_args, **self.op_kwargs)
           ^^^^^^^^^^^^^^^^^^^^^^^^^^^^^^^^^^^^^^^^^^^^^^^^^^^^^
  File "/opt/airflow/dags/dag_example.py", line 71, in load_reference_table_data
    cur.execute("CALL load_reference_table_data();")
psycopg2.errors.UniqueViolation: duplicate key value violates unique constraint "reference_table_pkey"
DETAIL:  Key (id)=(-1) already exists.
CONTEXT:  COPY reference_table, line 2
SQL statement "COPY raw.reference_table(
        id,
        nationality
    )
    FROM 'C:\\Users\\YaminChoudhury\\Documents\\Academy\\postgres\\F1 Ex\\Data\\nationalities.csv'
    WITH (
        FORMAT CSV,
        HEADER,
        DELIMITER ','
    )"
PL/pgSQL function load_reference_table_data() line 6 at SQL statement

[2024-05-30T11:36:24.157+0000] {taskinstance.py:1205} INFO - Marking task as FAILED. dag_id=stored_procedures, task_id=load_reference_table, execution_date=20240530T112608, start_date=20240530T113623, end_date=20240530T113624
[2024-05-30T11:36:24.169+0000] {standard_task_runner.py:110} ERROR - Failed to execute job 249 for task load_reference_table (duplicate key value violates unique constraint "reference_table_pkey"
DETAIL:  Key (id)=(-1) already exists.
CONTEXT:  COPY reference_table, line 2
SQL statement "COPY raw.reference_table(
        id,
        nationality
    )
    FROM 'C:\\Users\\YaminChoudhury\\Documents\\Academy\\postgres\\F1 Ex\\Data\\nationalities.csv'
    WITH (
        FORMAT CSV,
        HEADER,
        DELIMITER ','
    )"
PL/pgSQL function load_reference_table_data() line 6 at SQL statement
; 290)
[2024-05-30T11:36:24.208+0000] {local_task_job_runner.py:240} INFO - Task exited with return code 1
[2024-05-30T11:36:24.234+0000] {taskinstance.py:3482} INFO - 0 downstream tasks scheduled from follow-on schedule check
[2024-05-30T11:36:24.240+0000] {local_task_job_runner.py:222} INFO - ::endgroup::
